<?xml version="1.0" encoding="UTF-8"?>
<testng-results skipped="0" failed="2" ignored="0" total="3" passed="1">
  <reporter-output>
  </reporter-output>
  <suite name="Default suite" duration-ms="72847" started-at="2020-11-04T15:47:26Z" finished-at="2020-11-04T15:48:39Z">
    <groups>
      <group name="calculator">
        <method signature="TestCaseForScenarios.superSmartCalculator()[pri:0, instance:com.testData.TestCaseForScenarios@d2cc05a]" name="superSmartCalculator" class="com.testData.TestCaseForScenarios"/>
      </group> <!-- calculator -->
      <group name="Qaagility">
        <method signature="TestCaseForScenarios.qaagility()[pri:0, instance:com.testData.TestCaseForScenarios@d2cc05a]" name="qaagility" class="com.testData.TestCaseForScenarios"/>
      </group> <!-- Qaagility -->
      <group name="google">
        <method signature="TestCaseForScenarios.mapTest()[pri:0, instance:com.testData.TestCaseForScenarios@d2cc05a]" name="mapTest" class="com.testData.TestCaseForScenarios"/>
      </group> <!-- google -->
    </groups>
    <test name="Default test" duration-ms="72847" started-at="2020-11-04T15:47:26Z" finished-at="2020-11-04T15:48:39Z">
      <class name="com.testData.TestCaseForScenarios">
        <test-method status="FAIL" signature="mapTest()[pri:0, instance:com.testData.TestCaseForScenarios@d2cc05a]" name="mapTest" duration-ms="26608" started-at="2020-11-04T21:17:26Z" finished-at="2020-11-04T21:17:53Z">
          <exception class="java.lang.AssertionError">
            <message>
              <![CDATA[expected [Stadium] but found [Wankhede Stadium]]]>
            </message>
            <full-stacktrace>
              <![CDATA[java.lang.AssertionError: expected [Stadium] but found [Wankhede Stadium]
	at org.testng.Assert.fail(Assert.java:93)
	at org.testng.Assert.failNotEquals(Assert.java:512)
	at org.testng.Assert.assertEqualsImpl(Assert.java:134)
	at org.testng.Assert.assertEquals(Assert.java:115)
	at org.testng.Assert.assertEquals(Assert.java:189)
	at org.testng.Assert.assertEquals(Assert.java:199)
	at com.testData.TestCaseForScenarios.mapTest(TestCaseForScenarios.java:66)
	at sun.reflect.NativeMethodAccessorImpl.invoke0(Native Method)
	at sun.reflect.NativeMethodAccessorImpl.invoke(Unknown Source)
	at sun.reflect.DelegatingMethodAccessorImpl.invoke(Unknown Source)
	at java.lang.reflect.Method.invoke(Unknown Source)
	at org.testng.internal.MethodInvocationHelper.invokeMethod(MethodInvocationHelper.java:108)
	at org.testng.internal.Invoker.invokeMethod(Invoker.java:661)
	at org.testng.internal.Invoker.invokeTestMethod(Invoker.java:869)
	at org.testng.internal.Invoker.invokeTestMethods(Invoker.java:1193)
	at org.testng.internal.TestMethodWorker.invokeTestMethods(TestMethodWorker.java:126)
	at org.testng.internal.TestMethodWorker.run(TestMethodWorker.java:109)
	at org.testng.TestRunner.privateRun(TestRunner.java:744)
	at org.testng.TestRunner.run(TestRunner.java:602)
	at org.testng.SuiteRunner.runTest(SuiteRunner.java:380)
	at org.testng.SuiteRunner.runSequentially(SuiteRunner.java:375)
	at org.testng.SuiteRunner.privateRun(SuiteRunner.java:340)
	at org.testng.SuiteRunner.run(SuiteRunner.java:289)
	at org.testng.SuiteRunnerWorker.runSuite(SuiteRunnerWorker.java:52)
	at org.testng.SuiteRunnerWorker.run(SuiteRunnerWorker.java:86)
	at org.testng.TestNG.runSuitesSequentially(TestNG.java:1301)
	at org.testng.TestNG.runSuitesLocally(TestNG.java:1226)
	at org.testng.TestNG.runSuites(TestNG.java:1144)
	at org.testng.TestNG.run(TestNG.java:1115)
	at org.testng.remote.AbstractRemoteTestNG.run(AbstractRemoteTestNG.java:132)
	at org.testng.remote.RemoteTestNG.initAndRun(RemoteTestNG.java:230)
	at org.testng.remote.RemoteTestNG.main(RemoteTestNG.java:76)
]]>
            </full-stacktrace>
          </exception> <!-- java.lang.AssertionError -->
          <reporter-output>
          </reporter-output>
        </test-method> <!-- mapTest -->
        <test-method status="PASS" signature="qaagility()[pri:0, instance:com.testData.TestCaseForScenarios@d2cc05a]" name="qaagility" duration-ms="15316" started-at="2020-11-04T21:17:53Z" finished-at="2020-11-04T21:18:08Z">
          <reporter-output>
          </reporter-output>
        </test-method> <!-- qaagility -->
        <test-method status="FAIL" signature="superSmartCalculator()[pri:0, instance:com.testData.TestCaseForScenarios@d2cc05a]" name="superSmartCalculator" duration-ms="30865" started-at="2020-11-04T21:18:08Z" finished-at="2020-11-04T21:18:39Z">
          <exception class="java.lang.AssertionError">
            <message>
              <![CDATA[expected [-34] but found [9]]]>
            </message>
            <full-stacktrace>
              <![CDATA[java.lang.AssertionError: expected [-34] but found [9]
	at org.testng.Assert.fail(Assert.java:93)
	at org.testng.Assert.failNotEquals(Assert.java:512)
	at org.testng.Assert.assertEqualsImpl(Assert.java:134)
	at org.testng.Assert.assertEquals(Assert.java:115)
	at org.testng.Assert.assertEquals(Assert.java:189)
	at org.testng.Assert.assertEquals(Assert.java:199)
	at com.testData.TestCaseForScenarios.superSmartCalculator(TestCaseForScenarios.java:116)
	at sun.reflect.NativeMethodAccessorImpl.invoke0(Native Method)
	at sun.reflect.NativeMethodAccessorImpl.invoke(Unknown Source)
	at sun.reflect.DelegatingMethodAccessorImpl.invoke(Unknown Source)
	at java.lang.reflect.Method.invoke(Unknown Source)
	at org.testng.internal.MethodInvocationHelper.invokeMethod(MethodInvocationHelper.java:108)
	at org.testng.internal.Invoker.invokeMethod(Invoker.java:661)
	at org.testng.internal.Invoker.invokeTestMethod(Invoker.java:869)
	at org.testng.internal.Invoker.invokeTestMethods(Invoker.java:1193)
	at org.testng.internal.TestMethodWorker.invokeTestMethods(TestMethodWorker.java:126)
	at org.testng.internal.TestMethodWorker.run(TestMethodWorker.java:109)
	at org.testng.TestRunner.privateRun(TestRunner.java:744)
	at org.testng.TestRunner.run(TestRunner.java:602)
	at org.testng.SuiteRunner.runTest(SuiteRunner.java:380)
	at org.testng.SuiteRunner.runSequentially(SuiteRunner.java:375)
	at org.testng.SuiteRunner.privateRun(SuiteRunner.java:340)
	at org.testng.SuiteRunner.run(SuiteRunner.java:289)
	at org.testng.SuiteRunnerWorker.runSuite(SuiteRunnerWorker.java:52)
	at org.testng.SuiteRunnerWorker.run(SuiteRunnerWorker.java:86)
	at org.testng.TestNG.runSuitesSequentially(TestNG.java:1301)
	at org.testng.TestNG.runSuitesLocally(TestNG.java:1226)
	at org.testng.TestNG.runSuites(TestNG.java:1144)
	at org.testng.TestNG.run(TestNG.java:1115)
	at org.testng.remote.AbstractRemoteTestNG.run(AbstractRemoteTestNG.java:132)
	at org.testng.remote.RemoteTestNG.initAndRun(RemoteTestNG.java:230)
	at org.testng.remote.RemoteTestNG.main(RemoteTestNG.java:76)
]]>
            </full-stacktrace>
          </exception> <!-- java.lang.AssertionError -->
          <reporter-output>
          </reporter-output>
        </test-method> <!-- superSmartCalculator -->
      </class> <!-- com.testData.TestCaseForScenarios -->
    </test> <!-- Default test -->
  </suite> <!-- Default suite -->
</testng-results>
